Not Found: /friend/test
[03/Aug/2017 00:47:37] "DELETE /friend/test HTTP/1.1" 404 2076
Not Found: /friend
[03/Aug/2017 00:47:37] "POST /friend HTTP/1.1" 404 2059
Not Found: /chat_room/test
[03/Aug/2017 00:47:37] "DELETE /chat_room/test HTTP/1.1" 404 2085
[03/Aug/2017 00:47:37] "GET /keyboard HTTP/1.1" 200 74
[03/Aug/2017 00:47:40] "GET /keyboard HTTP/1.1" 200 74
[03/Aug/2017 00:47:42] "POST /message HTTP/1.1" 200 121
[03/Aug/2017 00:47:43] "POST /message HTTP/1.1" 200 212
[03/Aug/2017 00:47:44] "POST /message HTTP/1.1" 200 209
Performing system checks...

System check identified no issues (0 silenced).
August 03, 2017 - 00:47:37
Django version 1.11.4, using settings 'simzi.settings'
Starting development server at http://0.0.0.0:80/
Quit the server with CONTROL-C.
Performing system checks...

System check identified no issues (0 silenced).
August 03, 2017 - 00:49:39
Django version 1.11.4, using settings 'simzi.settings'
Starting development server at http://0.0.0.0:80/
Quit the server with CONTROL-C.
Performing system checks...

System check identified no issues (0 silenced).
August 03, 2017 - 00:50:11
Django version 1.11.4, using settings 'simzi.settings'
Starting development server at http://0.0.0.0:80/
Quit the server with CONTROL-C.
Performing system checks...

System check identified no issues (0 silenced).
August 03, 2017 - 00:50:26
Django version 1.11.4, using settings 'simzi.settings'
Starting development server at http://0.0.0.0:80/
Quit the server with CONTROL-C.
Internal Server Error: /message
Traceback (most recent call last):
  File "/usr/local/lib/python3.4/dist-packages/django/core/handlers/exception.py", line 41, in inner
    response = get_response(request)
  File "/usr/local/lib/python3.4/dist-packages/django/core/handlers/base.py", line 187, in _get_response
    response = self.process_exception_by_middleware(e, request)
  File "/usr/local/lib/python3.4/dist-packages/django/core/handlers/base.py", line 185, in _get_response
    response = wrapped_callback(request, *callback_args, **callback_kwargs)
  File "/usr/local/lib/python3.4/dist-packages/django/views/decorators/csrf.py", line 58, in wrapped_view
    return view_func(*args, **kwargs)
  File "/workspace/simzi/server/views.py", line 24, in message
    chat_room(request)
NameError: name 'chat_room' is not defined
[03/Aug/2017 00:50:33] "POST /message HTTP/1.1" 500 65130
Not Found: /friend/test
[03/Aug/2017 00:50:35] "DELETE /friend/test HTTP/1.1" 404 2076
Not Found: /friend
[03/Aug/2017 00:50:35] "POST /friend HTTP/1.1" 404 2059
Not Found: /chat_room/test
[03/Aug/2017 00:50:35] "DELETE /chat_room/test HTTP/1.1" 404 2085
[03/Aug/2017 00:50:35] "GET /keyboard HTTP/1.1" 200 74
Performing system checks...

System check identified no issues (0 silenced).
August 03, 2017 - 00:50:30
Django version 1.11.4, using settings 'simzi.settings'
Starting development server at http://0.0.0.0:80/
Quit the server with CONTROL-C.
Not Found: /friend/test
[03/Aug/2017 00:50:51] "DELETE /friend/test HTTP/1.1" 404 2076
Not Found: /friend
[03/Aug/2017 00:50:51] "POST /friend HTTP/1.1" 404 2059
Not Found: /chat_room/test
[03/Aug/2017 00:50:51] "DELETE /chat_room/test HTTP/1.1" 404 2085
[03/Aug/2017 00:50:51] "GET /keyboard HTTP/1.1" 200 74
[03/Aug/2017 00:50:55] "GET /keyboard HTTP/1.1" 200 74
[03/Aug/2017 00:50:56] "POST /message HTTP/1.1" 200 121
Performing system checks...

System check identified no issues (0 silenced).
August 03, 2017 - 00:50:51
Django version 1.11.4, using settings 'simzi.settings'
Starting development server at http://0.0.0.0:80/
Quit the server with CONTROL-C.
Internal Server Error: /message
Traceback (most recent call last):
  File "/usr/local/lib/python3.4/dist-packages/django/core/handlers/exception.py", line 41, in inner
    response = get_response(request)
  File "/usr/local/lib/python3.4/dist-packages/django/core/handlers/base.py", line 187, in _get_response
    response = self.process_exception_by_middleware(e, request)
  File "/usr/local/lib/python3.4/dist-packages/django/core/handlers/base.py", line 185, in _get_response
    response = wrapped_callback(request, *callback_args, **callback_kwargs)
  File "/usr/local/lib/python3.4/dist-packages/django/views/decorators/csrf.py", line 58, in wrapped_view
    return view_func(*args, **kwargs)
  File "/workspace/simzi/server/views.py", line 39, in message
    data = wannaone(request)
  File "/workspace/simzi/server/views.py", line 69, in wannaone
    "text" : "All I Wanna Do! " + content
NameError: name 'content' is not defined
[03/Aug/2017 00:51:16] "POST /message HTTP/1.1" 500 68756
Performing system checks...

System check identified no issues (0 silenced).
August 03, 2017 - 00:51:14
Django version 1.11.4, using settings 'simzi.settings'
Starting development server at http://0.0.0.0:80/
Quit the server with CONTROL-C.
Not Found: /friend/test
[03/Aug/2017 00:51:35] "DELETE /friend/test HTTP/1.1" 404 2076
Not Found: /friend
[03/Aug/2017 00:51:35] "POST /friend HTTP/1.1" 404 2059
Not Found: /chat_room/test
[03/Aug/2017 00:51:35] "DELETE /chat_room/test HTTP/1.1" 404 2085
[03/Aug/2017 00:51:35] "GET /keyboard HTTP/1.1" 200 74
[03/Aug/2017 00:51:38] "GET /keyboard HTTP/1.1" 200 74
[03/Aug/2017 00:51:39] "POST /message HTTP/1.1" 200 129
[03/Aug/2017 00:51:41] "POST /message HTTP/1.1" 200 129
[03/Aug/2017 00:51:42] "POST /message HTTP/1.1" 200 209
Performing system checks...

System check identified no issues (0 silenced).
August 03, 2017 - 00:51:30
Django version 1.11.4, using settings 'simzi.settings'
Starting development server at http://0.0.0.0:80/
Quit the server with CONTROL-C.
Performing system checks...

System check identified no issues (0 silenced).
August 03, 2017 - 00:51:48
Django version 1.11.4, using settings 'simzi.settings'
Starting development server at http://0.0.0.0:80/
Quit the server with CONTROL-C.
Performing system checks...

System check identified no issues (0 silenced).
August 03, 2017 - 00:52:10
Django version 1.11.4, using settings 'simzi.settings'
Starting development server at http://0.0.0.0:80/
Quit the server with CONTROL-C.
Performing system checks...

System check identified no issues (0 silenced).
August 03, 2017 - 00:52:25
Django version 1.11.4, using settings 'simzi.settings'
Starting development server at http://0.0.0.0:80/
Quit the server with CONTROL-C.
Not Found: /friend/test
[03/Aug/2017 00:52:36] "DELETE /friend/test HTTP/1.1" 404 2076
Not Found: /friend
[03/Aug/2017 00:52:36] "POST /friend HTTP/1.1" 404 2059
Not Found: /chat_room/test
[03/Aug/2017 00:52:36] "DELETE /chat_room/test HTTP/1.1" 404 2085
[03/Aug/2017 00:52:36] "GET /keyboard HTTP/1.1" 200 84
[03/Aug/2017 00:52:40] "GET /keyboard HTTP/1.1" 200 84
[03/Aug/2017 00:52:41] "POST /message HTTP/1.1" 200 212
[03/Aug/2017 00:52:42] "POST /message HTTP/1.1" 200 138
[03/Aug/2017 00:52:44] "POST /message HTTP/1.1" 200 209
[03/Aug/2017 00:52:56] "GET /keyboard HTTP/1.1" 200 84
[03/Aug/2017 00:52:58] "POST /message HTTP/1.1" 200 212
Performing system checks...

System check identified no issues (0 silenced).
August 03, 2017 - 00:52:30
Django version 1.11.4, using settings 'simzi.settings'
Starting development server at http://0.0.0.0:80/
Quit the server with CONTROL-C.
Performing system checks...

System check identified no issues (0 silenced).
August 03, 2017 - 00:53:01
Django version 1.11.4, using settings 'simzi.settings'
Starting development server at http://0.0.0.0:80/
Quit the server with CONTROL-C.
Performing system checks...

System check identified no issues (0 silenced).
August 03, 2017 - 00:53:09
Django version 1.11.4, using settings 'simzi.settings'
Starting development server at http://0.0.0.0:80/
Quit the server with CONTROL-C.
Performing system checks...

System check identified no issues (0 silenced).
August 03, 2017 - 00:53:14
Django version 1.11.4, using settings 'simzi.settings'
Starting development server at http://0.0.0.0:80/
Quit the server with CONTROL-C.
Performing system checks...

System check identified no issues (0 silenced).
August 03, 2017 - 00:53:28
Django version 1.11.4, using settings 'simzi.settings'
Starting development server at http://0.0.0.0:80/
Quit the server with CONTROL-C.
Performing system checks...

System check identified no issues (0 silenced).
August 03, 2017 - 00:53:42
Django version 1.11.4, using settings 'simzi.settings'
Starting development server at http://0.0.0.0:80/
Quit the server with CONTROL-C.
[03/Aug/2017 00:53:53] "GET /keyboard HTTP/1.1" 200 74
Not Found: /friend/test
[03/Aug/2017 00:53:56] "DELETE /friend/test HTTP/1.1" 404 2076
Not Found: /friend
[03/Aug/2017 00:53:56] "POST /friend HTTP/1.1" 404 2059
Not Found: /chat_room/test
[03/Aug/2017 00:53:56] "DELETE /chat_room/test HTTP/1.1" 404 2085
[03/Aug/2017 00:53:56] "GET /keyboard HTTP/1.1" 200 74
Not Found: /friend/test
[03/Aug/2017 00:53:57] "DELETE /friend/test HTTP/1.1" 404 2076
Not Found: /friend
[03/Aug/2017 00:53:57] "POST /friend HTTP/1.1" 404 2059
Not Found: /chat_room/test
[03/Aug/2017 00:53:57] "DELETE /chat_room/test HTTP/1.1" 404 2085
[03/Aug/2017 00:53:57] "GET /keyboard HTTP/1.1" 200 74
[03/Aug/2017 00:53:59] "GET /keyboard HTTP/1.1" 200 74
[03/Aug/2017 00:54:01] "POST /message HTTP/1.1" 200 228
[03/Aug/2017 00:54:03] "POST /message HTTP/1.1" 200 135
[03/Aug/2017 00:54:09] "POST /message HTTP/1.1" 200 154
Performing system checks...

System check identified no issues (0 silenced).
August 03, 2017 - 00:53:51
Django version 1.11.4, using settings 'simzi.settings'
Starting development server at http://0.0.0.0:80/
Quit the server with CONTROL-C.
Performing system checks...

System check identified no issues (0 silenced).
August 03, 2017 - 00:54:42
Django version 1.11.4, using settings 'simzi.settings'
Starting development server at http://0.0.0.0:80/
Quit the server with CONTROL-C.
Performing system checks...

System check identified no issues (0 silenced).
August 03, 2017 - 00:54:54
Django version 1.11.4, using settings 'simzi.settings'
Starting development server at http://0.0.0.0:80/
Quit the server with CONTROL-C.
Performing system checks...

System check identified no issues (0 silenced).
August 03, 2017 - 00:55:05
Django version 1.11.4, using settings 'simzi.settings'
Starting development server at http://0.0.0.0:80/
Quit the server with CONTROL-C.
Performing system checks...

System check identified no issues (0 silenced).
August 03, 2017 - 00:55:12
Django version 1.11.4, using settings 'simzi.settings'
Starting development server at http://0.0.0.0:80/
Quit the server with CONTROL-C.
Performing system checks...

System check identified no issues (0 silenced).
August 03, 2017 - 00:55:18
Django version 1.11.4, using settings 'simzi.settings'
Starting development server at http://0.0.0.0:80/
Quit the server with CONTROL-C.
Performing system checks...

System check identified no issues (0 silenced).
August 03, 2017 - 00:55:23
Django version 1.11.4, using settings 'simzi.settings'
Starting development server at http://0.0.0.0:80/
Quit the server with CONTROL-C.
Performing system checks...

System check identified no issues (0 silenced).
August 03, 2017 - 00:56:03
Django version 1.11.4, using settings 'simzi.settings'
Starting development server at http://0.0.0.0:80/
Quit the server with CONTROL-C.
Performing system checks...

System check identified no issues (0 silenced).
August 03, 2017 - 00:56:09
Django version 1.11.4, using settings 'simzi.settings'
Starting development server at http://0.0.0.0:80/
Quit the server with CONTROL-C.
Performing system checks...

System check identified no issues (0 silenced).
August 03, 2017 - 00:56:31
Django version 1.11.4, using settings 'simzi.settings'
Starting development server at http://0.0.0.0:80/
Quit the server with CONTROL-C.
Unhandled exception in thread started by <function check_errors.<locals>.wrapper at 0x7f66a5ba8d08>
Traceback (most recent call last):
  File "/usr/local/lib/python3.4/dist-packages/django/utils/autoreload.py", line 228, in wrapper
    fn(*args, **kwargs)
  File "/usr/local/lib/python3.4/dist-packages/django/core/management/commands/runserver.py", line 125, in inner_run
    self.check(display_num_errors=True)
  File "/usr/local/lib/python3.4/dist-packages/django/core/management/base.py", line 359, in check
    include_deployment_checks=include_deployment_checks,
  File "/usr/local/lib/python3.4/dist-packages/django/core/management/base.py", line 346, in _run_checks
    return checks.run_checks(**kwargs)
  File "/usr/local/lib/python3.4/dist-packages/django/core/checks/registry.py", line 81, in run_checks
    new_errors = check(app_configs=app_configs)
  File "/usr/local/lib/python3.4/dist-packages/django/core/checks/urls.py", line 16, in check_url_config
    return check_resolver(resolver)
  File "/usr/local/lib/python3.4/dist-packages/django/core/checks/urls.py", line 26, in check_resolver
    return check_method()
  File "/usr/local/lib/python3.4/dist-packages/django/urls/resolvers.py", line 254, in check
    for pattern in self.url_patterns:
  File "/usr/local/lib/python3.4/dist-packages/django/utils/functional.py", line 35, in __get__
    res = instance.__dict__[self.name] = self.func(instance)
  File "/usr/local/lib/python3.4/dist-packages/django/urls/resolvers.py", line 405, in url_patterns
    patterns = getattr(self.urlconf_module, "urlpatterns", self.urlconf_module)
  File "/usr/local/lib/python3.4/dist-packages/django/utils/functional.py", line 35, in __get__
    res = instance.__dict__[self.name] = self.func(instance)
  File "/usr/local/lib/python3.4/dist-packages/django/urls/resolvers.py", line 398, in urlconf_module
    return import_module(self.urlconf_name)
  File "/usr/lib/python3.4/importlib/__init__.py", line 109, in import_module
    return _bootstrap._gcd_import(name[level:], package, level)
  File "<frozen importlib._bootstrap>", line 2254, in _gcd_import
  File "<frozen importlib._bootstrap>", line 2237, in _find_and_load
  File "<frozen importlib._bootstrap>", line 2226, in _find_and_load_unlocked
  File "<frozen importlib._bootstrap>", line 1200, in _load_unlocked
  File "<frozen importlib._bootstrap>", line 1129, in _exec
  File "<frozen importlib._bootstrap>", line 1471, in exec_module
  File "<frozen importlib._bootstrap>", line 321, in _call_with_frames_removed
  File "/workspace/simzi/simzi/urls.py", line 3, in <module>
    from server import views
  File "/workspace/simzi/server/views.py", line 75
    "message_button": {
                    ^
SyntaxError: invalid syntax
Performing system checks...

Unhandled exception in thread started by <function check_errors.<locals>.wrapper at 0x7fd7e3290d08>
Traceback (most recent call last):
  File "/usr/local/lib/python3.4/dist-packages/django/utils/autoreload.py", line 228, in wrapper
    fn(*args, **kwargs)
  File "/usr/local/lib/python3.4/dist-packages/django/core/management/commands/runserver.py", line 125, in inner_run
    self.check(display_num_errors=True)
  File "/usr/local/lib/python3.4/dist-packages/django/core/management/base.py", line 359, in check
    include_deployment_checks=include_deployment_checks,
  File "/usr/local/lib/python3.4/dist-packages/django/core/management/base.py", line 346, in _run_checks
    return checks.run_checks(**kwargs)
  File "/usr/local/lib/python3.4/dist-packages/django/core/checks/registry.py", line 81, in run_checks
    new_errors = check(app_configs=app_configs)
  File "/usr/local/lib/python3.4/dist-packages/django/core/checks/urls.py", line 16, in check_url_config
    return check_resolver(resolver)
  File "/usr/local/lib/python3.4/dist-packages/django/core/checks/urls.py", line 26, in check_resolver
    return check_method()
  File "/usr/local/lib/python3.4/dist-packages/django/urls/resolvers.py", line 254, in check
    for pattern in self.url_patterns:
  File "/usr/local/lib/python3.4/dist-packages/django/utils/functional.py", line 35, in __get__
    res = instance.__dict__[self.name] = self.func(instance)
  File "/usr/local/lib/python3.4/dist-packages/django/urls/resolvers.py", line 405, in url_patterns
    patterns = getattr(self.urlconf_module, "urlpatterns", self.urlconf_module)
  File "/usr/local/lib/python3.4/dist-packages/django/utils/functional.py", line 35, in __get__
    res = instance.__dict__[self.name] = self.func(instance)
  File "/usr/local/lib/python3.4/dist-packages/django/urls/resolvers.py", line 398, in urlconf_module
    return import_module(self.urlconf_name)
  File "/usr/lib/python3.4/importlib/__init__.py", line 109, in import_module
    return _bootstrap._gcd_import(name[level:], package, level)
  File "<frozen importlib._bootstrap>", line 2254, in _gcd_import
  File "<frozen importlib._bootstrap>", line 2237, in _find_and_load
  File "<frozen importlib._bootstrap>", line 2226, in _find_and_load_unlocked
  File "<frozen importlib._bootstrap>", line 1200, in _load_unlocked
  File "<frozen importlib._bootstrap>", line 1129, in _exec
  File "<frozen importlib._bootstrap>", line 1471, in exec_module
  File "<frozen importlib._bootstrap>", line 321, in _call_with_frames_removed
  File "/workspace/simzi/simzi/urls.py", line 3, in <module>
    from server import views
  File "/workspace/simzi/server/views.py", line 41
    data = 
          ^
SyntaxError: invalid syntax
Performing system checks...

Unhandled exception in thread started by <function check_errors.<locals>.wrapper at 0x7fc9ffbc8d08>
Traceback (most recent call last):
  File "/usr/local/lib/python3.4/dist-packages/django/utils/autoreload.py", line 228, in wrapper
    fn(*args, **kwargs)
  File "/usr/local/lib/python3.4/dist-packages/django/core/management/commands/runserver.py", line 125, in inner_run
    self.check(display_num_errors=True)
  File "/usr/local/lib/python3.4/dist-packages/django/core/management/base.py", line 359, in check
    include_deployment_checks=include_deployment_checks,
  File "/usr/local/lib/python3.4/dist-packages/django/core/management/base.py", line 346, in _run_checks
    return checks.run_checks(**kwargs)
  File "/usr/local/lib/python3.4/dist-packages/django/core/checks/registry.py", line 81, in run_checks
    new_errors = check(app_configs=app_configs)
  File "/usr/local/lib/python3.4/dist-packages/django/core/checks/urls.py", line 16, in check_url_config
    return check_resolver(resolver)
  File "/usr/local/lib/python3.4/dist-packages/django/core/checks/urls.py", line 26, in check_resolver
    return check_method()
  File "/usr/local/lib/python3.4/dist-packages/django/urls/resolvers.py", line 254, in check
    for pattern in self.url_patterns:
  File "/usr/local/lib/python3.4/dist-packages/django/utils/functional.py", line 35, in __get__
    res = instance.__dict__[self.name] = self.func(instance)
  File "/usr/local/lib/python3.4/dist-packages/django/urls/resolvers.py", line 405, in url_patterns
    patterns = getattr(self.urlconf_module, "urlpatterns", self.urlconf_module)
  File "/usr/local/lib/python3.4/dist-packages/django/utils/functional.py", line 35, in __get__
    res = instance.__dict__[self.name] = self.func(instance)
  File "/usr/local/lib/python3.4/dist-packages/django/urls/resolvers.py", line 398, in urlconf_module
    return import_module(self.urlconf_name)
  File "/usr/lib/python3.4/importlib/__init__.py", line 109, in import_module
    return _bootstrap._gcd_import(name[level:], package, level)
  File "<frozen importlib._bootstrap>", line 2254, in _gcd_import
  File "<frozen importlib._bootstrap>", line 2237, in _find_and_load
  File "<frozen importlib._bootstrap>", line 2226, in _find_and_load_unlocked
  File "<frozen importlib._bootstrap>", line 1200, in _load_unlocked
  File "<frozen importlib._bootstrap>", line 1129, in _exec
  File "<frozen importlib._bootstrap>", line 1471, in exec_module
  File "<frozen importlib._bootstrap>", line 321, in _call_with_frames_removed
  File "/workspace/simzi/simzi/urls.py", line 3, in <module>
    from server import views
  File "/workspace/simzi/server/views.py", line 63
    "message_button": {
                    ^
SyntaxError: invalid syntax
Performing system checks...

Unhandled exception in thread started by <function check_errors.<locals>.wrapper at 0x7f165b864d08>
Traceback (most recent call last):
  File "/usr/local/lib/python3.4/dist-packages/django/utils/autoreload.py", line 228, in wrapper
    fn(*args, **kwargs)
  File "/usr/local/lib/python3.4/dist-packages/django/core/management/commands/runserver.py", line 125, in inner_run
    self.check(display_num_errors=True)
  File "/usr/local/lib/python3.4/dist-packages/django/core/management/base.py", line 359, in check
    include_deployment_checks=include_deployment_checks,
  File "/usr/local/lib/python3.4/dist-packages/django/core/management/base.py", line 346, in _run_checks
    return checks.run_checks(**kwargs)
  File "/usr/local/lib/python3.4/dist-packages/django/core/checks/registry.py", line 81, in run_checks
    new_errors = check(app_configs=app_configs)
  File "/usr/local/lib/python3.4/dist-packages/django/core/checks/urls.py", line 16, in check_url_config
    return check_resolver(resolver)
  File "/usr/local/lib/python3.4/dist-packages/django/core/checks/urls.py", line 26, in check_resolver
    return check_method()
  File "/usr/local/lib/python3.4/dist-packages/django/urls/resolvers.py", line 254, in check
    for pattern in self.url_patterns:
  File "/usr/local/lib/python3.4/dist-packages/django/utils/functional.py", line 35, in __get__
    res = instance.__dict__[self.name] = self.func(instance)
  File "/usr/local/lib/python3.4/dist-packages/django/urls/resolvers.py", line 405, in url_patterns
    patterns = getattr(self.urlconf_module, "urlpatterns", self.urlconf_module)
  File "/usr/local/lib/python3.4/dist-packages/django/utils/functional.py", line 35, in __get__
    res = instance.__dict__[self.name] = self.func(instance)
  File "/usr/local/lib/python3.4/dist-packages/django/urls/resolvers.py", line 398, in urlconf_module
    return import_module(self.urlconf_name)
  File "/usr/lib/python3.4/importlib/__init__.py", line 109, in import_module
    return _bootstrap._gcd_import(name[level:], package, level)
  File "<frozen importlib._bootstrap>", line 2254, in _gcd_import
  File "<frozen importlib._bootstrap>", line 2237, in _find_and_load
  File "<frozen importlib._bootstrap>", line 2226, in _find_and_load_unlocked
  File "<frozen importlib._bootstrap>", line 1200, in _load_unlocked
  File "<frozen importlib._bootstrap>", line 1129, in _exec
  File "<frozen importlib._bootstrap>", line 1471, in exec_module
  File "<frozen importlib._bootstrap>", line 321, in _call_with_frames_removed
  File "/workspace/simzi/simzi/urls.py", line 3, in <module>
    from server import views
  File "/workspace/simzi/server/views.py", line 63
    "message_button": {
                    ^
SyntaxError: invalid syntax
Performing system checks...

Performing system checks...

System check identified no issues (0 silenced).
August 03, 2017 - 00:57:21
Django version 1.11.4, using settings 'simzi.settings'
Starting development server at http://0.0.0.0:80/
Quit the server with CONTROL-C.
[03/Aug/2017 00:57:29] "POST /message HTTP/1.1" 200 228
[03/Aug/2017 00:57:31] "POST /message HTTP/1.1" 200 225
[03/Aug/2017 00:57:32] "POST /message HTTP/1.1" 200 154
Performing system checks...

System check identified no issues (0 silenced).
August 03, 2017 - 00:57:26
Django version 1.11.4, using settings 'simzi.settings'
Starting development server at http://0.0.0.0:80/
Quit the server with CONTROL-C.
Performing system checks...

System check identified no issues (0 silenced).
August 03, 2017 - 00:57:51
Django version 1.11.4, using settings 'simzi.settings'
Starting development server at http://0.0.0.0:80/
Quit the server with CONTROL-C.
Performing system checks...

System check identified no issues (0 silenced).
August 03, 2017 - 00:57:56
Django version 1.11.4, using settings 'simzi.settings'
Starting development server at http://0.0.0.0:80/
Quit the server with CONTROL-C.
Performing system checks...

System check identified no issues (0 silenced).
August 03, 2017 - 00:58:07
Django version 1.11.4, using settings 'simzi.settings'
Starting development server at http://0.0.0.0:80/
Quit the server with CONTROL-C.
Performing system checks...

System check identified no issues (0 silenced).
August 03, 2017 - 00:58:17
Django version 1.11.4, using settings 'simzi.settings'
Starting development server at http://0.0.0.0:80/
Quit the server with CONTROL-C.
[03/Aug/2017 00:58:26] "POST /message HTTP/1.1" 200 228
[03/Aug/2017 00:58:27] "POST /message HTTP/1.1" 200 225
Performing system checks...

System check identified no issues (0 silenced).
August 03, 2017 - 00:58:26
Django version 1.11.4, using settings 'simzi.settings'
Starting development server at http://0.0.0.0:80/
Quit the server with CONTROL-C.
[03/Aug/2017 00:59:01] "POST /message HTTP/1.1" 200 135
[03/Aug/2017 00:59:12] "POST /message HTTP/1.1" 200 154
[03/Aug/2017 00:59:13] "POST /message HTTP/1.1" 200 135
Performing system checks...

System check identified no issues (0 silenced).
August 03, 2017 - 00:59:00
Django version 1.11.4, using settings 'simzi.settings'
Starting development server at http://0.0.0.0:80/
Quit the server with CONTROL-C.
Unhandled exception in thread started by <function check_errors.<locals>.wrapper at 0x7fa0b8677d08>
Traceback (most recent call last):
  File "/usr/local/lib/python3.4/dist-packages/django/utils/autoreload.py", line 228, in wrapper
    fn(*args, **kwargs)
  File "/usr/local/lib/python3.4/dist-packages/django/core/management/commands/runserver.py", line 125, in inner_run
    self.check(display_num_errors=True)
  File "/usr/local/lib/python3.4/dist-packages/django/core/management/base.py", line 359, in check
    include_deployment_checks=include_deployment_checks,
  File "/usr/local/lib/python3.4/dist-packages/django/core/management/base.py", line 346, in _run_checks
    return checks.run_checks(**kwargs)
  File "/usr/local/lib/python3.4/dist-packages/django/core/checks/registry.py", line 81, in run_checks
    new_errors = check(app_configs=app_configs)
  File "/usr/local/lib/python3.4/dist-packages/django/core/checks/urls.py", line 16, in check_url_config
    return check_resolver(resolver)
  File "/usr/local/lib/python3.4/dist-packages/django/core/checks/urls.py", line 26, in check_resolver
    return check_method()
  File "/usr/local/lib/python3.4/dist-packages/django/urls/resolvers.py", line 254, in check
    for pattern in self.url_patterns:
  File "/usr/local/lib/python3.4/dist-packages/django/utils/functional.py", line 35, in __get__
    res = instance.__dict__[self.name] = self.func(instance)
  File "/usr/local/lib/python3.4/dist-packages/django/urls/resolvers.py", line 405, in url_patterns
    patterns = getattr(self.urlconf_module, "urlpatterns", self.urlconf_module)
  File "/usr/local/lib/python3.4/dist-packages/django/utils/functional.py", line 35, in __get__
    res = instance.__dict__[self.name] = self.func(instance)
  File "/usr/local/lib/python3.4/dist-packages/django/urls/resolvers.py", line 398, in urlconf_module
    return import_module(self.urlconf_name)
  File "/usr/lib/python3.4/importlib/__init__.py", line 109, in import_module
    return _bootstrap._gcd_import(name[level:], package, level)
  File "<frozen importlib._bootstrap>", line 2254, in _gcd_import
  File "<frozen importlib._bootstrap>", line 2237, in _find_and_load
  File "<frozen importlib._bootstrap>", line 2226, in _find_and_load_unlocked
  File "<frozen importlib._bootstrap>", line 1200, in _load_unlocked
  File "<frozen importlib._bootstrap>", line 1129, in _exec
  File "<frozen importlib._bootstrap>", line 1471, in exec_module
  File "<frozen importlib._bootstrap>", line 321, in _call_with_frames_removed
  File "/workspace/simzi/simzi/urls.py", line 3, in <module>
    from server import views
  File "/workspace/simzi/server/views.py", line 28
    elif:
        ^
SyntaxError: invalid syntax
Performing system checks...

Performing system checks...

System check identified no issues (0 silenced).
August 03, 2017 - 01:00:32
Django version 1.11.4, using settings 'simzi.settings'
Starting development server at http://0.0.0.0:80/
Quit the server with CONTROL-C.
[03/Aug/2017 01:00:39] "GET /keyboard HTTP/1.1" 200 74
[03/Aug/2017 01:00:41] "POST /message HTTP/1.1" 200 228
[03/Aug/2017 01:00:41] "POST /message HTTP/1.1" 200 225
[03/Aug/2017 01:00:42] "POST /message HTTP/1.1" 200 154
[03/Aug/2017 01:00:44] "POST /message HTTP/1.1" 200 228
[03/Aug/2017 01:00:44] "POST /message HTTP/1.1" 200 228
Performing system checks...

System check identified no issues (0 silenced).
August 03, 2017 - 01:00:37
Django version 1.11.4, using settings 'simzi.settings'
Starting development server at http://0.0.0.0:80/
Quit the server with CONTROL-C.
Unhandled exception in thread started by <function check_errors.<locals>.wrapper at 0x7fd65b11bd08>
Traceback (most recent call last):
  File "/usr/local/lib/python3.4/dist-packages/django/utils/autoreload.py", line 228, in wrapper
    fn(*args, **kwargs)
  File "/usr/local/lib/python3.4/dist-packages/django/core/management/commands/runserver.py", line 125, in inner_run
    self.check(display_num_errors=True)
  File "/usr/local/lib/python3.4/dist-packages/django/core/management/base.py", line 359, in check
    include_deployment_checks=include_deployment_checks,
  File "/usr/local/lib/python3.4/dist-packages/django/core/management/base.py", line 346, in _run_checks
    return checks.run_checks(**kwargs)
  File "/usr/local/lib/python3.4/dist-packages/django/core/checks/registry.py", line 81, in run_checks
    new_errors = check(app_configs=app_configs)
  File "/usr/local/lib/python3.4/dist-packages/django/core/checks/urls.py", line 16, in check_url_config
    return check_resolver(resolver)
  File "/usr/local/lib/python3.4/dist-packages/django/core/checks/urls.py", line 26, in check_resolver
    return check_method()
  File "/usr/local/lib/python3.4/dist-packages/django/urls/resolvers.py", line 254, in check
    for pattern in self.url_patterns:
  File "/usr/local/lib/python3.4/dist-packages/django/utils/functional.py", line 35, in __get__
    res = instance.__dict__[self.name] = self.func(instance)
  File "/usr/local/lib/python3.4/dist-packages/django/urls/resolvers.py", line 405, in url_patterns
    patterns = getattr(self.urlconf_module, "urlpatterns", self.urlconf_module)
  File "/usr/local/lib/python3.4/dist-packages/django/utils/functional.py", line 35, in __get__
    res = instance.__dict__[self.name] = self.func(instance)
  File "/usr/local/lib/python3.4/dist-packages/django/urls/resolvers.py", line 398, in urlconf_module
    return import_module(self.urlconf_name)
  File "/usr/lib/python3.4/importlib/__init__.py", line 109, in import_module
    return _bootstrap._gcd_import(name[level:], package, level)
  File "<frozen importlib._bootstrap>", line 2254, in _gcd_import
  File "<frozen importlib._bootstrap>", line 2237, in _find_and_load
  File "<frozen importlib._bootstrap>", line 2226, in _find_and_load_unlocked
  File "<frozen importlib._bootstrap>", line 1200, in _load_unlocked
  File "<frozen importlib._bootstrap>", line 1129, in _exec
  File "<frozen importlib._bootstrap>", line 1471, in exec_module
  File "<frozen importlib._bootstrap>", line 321, in _call_with_frames_removed
  File "/workspace/simzi/simzi/urls.py", line 3, in <module>
    from server import views
  File "/workspace/simzi/server/views.py", line 28
    elif contetn == u"처음으로"
                           ^
SyntaxError: invalid syntax
Performing system checks...

Unhandled exception in thread started by <function check_errors.<locals>.wrapper at 0x7f1e1cb77d08>
Traceback (most recent call last):
  File "/usr/local/lib/python3.4/dist-packages/django/utils/autoreload.py", line 228, in wrapper
    fn(*args, **kwargs)
  File "/usr/local/lib/python3.4/dist-packages/django/core/management/commands/runserver.py", line 125, in inner_run
    self.check(display_num_errors=True)
  File "/usr/local/lib/python3.4/dist-packages/django/core/management/base.py", line 359, in check
    include_deployment_checks=include_deployment_checks,
  File "/usr/local/lib/python3.4/dist-packages/django/core/management/base.py", line 346, in _run_checks
    return checks.run_checks(**kwargs)
  File "/usr/local/lib/python3.4/dist-packages/django/core/checks/registry.py", line 81, in run_checks
    new_errors = check(app_configs=app_configs)
  File "/usr/local/lib/python3.4/dist-packages/django/core/checks/urls.py", line 16, in check_url_config
    return check_resolver(resolver)
  File "/usr/local/lib/python3.4/dist-packages/django/core/checks/urls.py", line 26, in check_resolver
    return check_method()
  File "/usr/local/lib/python3.4/dist-packages/django/urls/resolvers.py", line 254, in check
    for pattern in self.url_patterns:
  File "/usr/local/lib/python3.4/dist-packages/django/utils/functional.py", line 35, in __get__
    res = instance.__dict__[self.name] = self.func(instance)
  File "/usr/local/lib/python3.4/dist-packages/django/urls/resolvers.py", line 405, in url_patterns
    patterns = getattr(self.urlconf_module, "urlpatterns", self.urlconf_module)
  File "/usr/local/lib/python3.4/dist-packages/django/utils/functional.py", line 35, in __get__
    res = instance.__dict__[self.name] = self.func(instance)
  File "/usr/local/lib/python3.4/dist-packages/django/urls/resolvers.py", line 398, in urlconf_module
    return import_module(self.urlconf_name)
  File "/usr/lib/python3.4/importlib/__init__.py", line 109, in import_module
    return _bootstrap._gcd_import(name[level:], package, level)
  File "<frozen importlib._bootstrap>", line 2254, in _gcd_import
  File "<frozen importlib._bootstrap>", line 2237, in _find_and_load
  File "<frozen importlib._bootstrap>", line 2226, in _find_and_load_unlocked
  File "<frozen importlib._bootstrap>", line 1200, in _load_unlocked
  File "<frozen importlib._bootstrap>", line 1129, in _exec
  File "<frozen importlib._bootstrap>", line 1471, in exec_module
  File "<frozen importlib._bootstrap>", line 321, in _call_with_frames_removed
  File "/workspace/simzi/simzi/urls.py", line 3, in <module>
    from server import views
  File "/workspace/simzi/server/views.py", line 28
    elif contetn == u"처음으로"
                           ^
SyntaxError: invalid syntax
Performing system checks...

Unhandled exception in thread started by <function check_errors.<locals>.wrapper at 0x7f316ba4bd08>
Traceback (most recent call last):
  File "/usr/local/lib/python3.4/dist-packages/django/utils/autoreload.py", line 228, in wrapper
    fn(*args, **kwargs)
  File "/usr/local/lib/python3.4/dist-packages/django/core/management/commands/runserver.py", line 125, in inner_run
    self.check(display_num_errors=True)
  File "/usr/local/lib/python3.4/dist-packages/django/core/management/base.py", line 359, in check
    include_deployment_checks=include_deployment_checks,
  File "/usr/local/lib/python3.4/dist-packages/django/core/management/base.py", line 346, in _run_checks
    return checks.run_checks(**kwargs)
  File "/usr/local/lib/python3.4/dist-packages/django/core/checks/registry.py", line 81, in run_checks
    new_errors = check(app_configs=app_configs)
  File "/usr/local/lib/python3.4/dist-packages/django/core/checks/urls.py", line 16, in check_url_config
    return check_resolver(resolver)
  File "/usr/local/lib/python3.4/dist-packages/django/core/checks/urls.py", line 26, in check_resolver
    return check_method()
  File "/usr/local/lib/python3.4/dist-packages/django/urls/resolvers.py", line 254, in check
    for pattern in self.url_patterns:
  File "/usr/local/lib/python3.4/dist-packages/django/utils/functional.py", line 35, in __get__
    res = instance.__dict__[self.name] = self.func(instance)
  File "/usr/local/lib/python3.4/dist-packages/django/urls/resolvers.py", line 405, in url_patterns
    patterns = getattr(self.urlconf_module, "urlpatterns", self.urlconf_module)
  File "/usr/local/lib/python3.4/dist-packages/django/utils/functional.py", line 35, in __get__
    res = instance.__dict__[self.name] = self.func(instance)
  File "/usr/local/lib/python3.4/dist-packages/django/urls/resolvers.py", line 398, in urlconf_module
    return import_module(self.urlconf_name)
  File "/usr/lib/python3.4/importlib/__init__.py", line 109, in import_module
    return _bootstrap._gcd_import(name[level:], package, level)
  File "<frozen importlib._bootstrap>", line 2254, in _gcd_import
  File "<frozen importlib._bootstrap>", line 2237, in _find_and_load
  File "<frozen importlib._bootstrap>", line 2226, in _find_and_load_unlocked
  File "<frozen importlib._bootstrap>", line 1200, in _load_unlocked
  File "<frozen importlib._bootstrap>", line 1129, in _exec
  File "<frozen importlib._bootstrap>", line 1471, in exec_module
  File "<frozen importlib._bootstrap>", line 321, in _call_with_frames_removed
  File "/workspace/simzi/simzi/urls.py", line 3, in <module>
    from server import views
  File "/workspace/simzi/server/views.py", line 28
    elif contetn == u"처음으로"
                           ^
SyntaxError: invalid syntax
Performing system checks...

Unhandled exception in thread started by <function check_errors.<locals>.wrapper at 0x7f0d479d7d08>
Traceback (most recent call last):
  File "/usr/local/lib/python3.4/dist-packages/django/utils/autoreload.py", line 228, in wrapper
    fn(*args, **kwargs)
  File "/usr/local/lib/python3.4/dist-packages/django/core/management/commands/runserver.py", line 125, in inner_run
    self.check(display_num_errors=True)
  File "/usr/local/lib/python3.4/dist-packages/django/core/management/base.py", line 359, in check
    include_deployment_checks=include_deployment_checks,
  File "/usr/local/lib/python3.4/dist-packages/django/core/management/base.py", line 346, in _run_checks
    return checks.run_checks(**kwargs)
  File "/usr/local/lib/python3.4/dist-packages/django/core/checks/registry.py", line 81, in run_checks
    new_errors = check(app_configs=app_configs)
  File "/usr/local/lib/python3.4/dist-packages/django/core/checks/urls.py", line 16, in check_url_config
    return check_resolver(resolver)
  File "/usr/local/lib/python3.4/dist-packages/django/core/checks/urls.py", line 26, in check_resolver
    return check_method()
  File "/usr/local/lib/python3.4/dist-packages/django/urls/resolvers.py", line 254, in check
    for pattern in self.url_patterns:
  File "/usr/local/lib/python3.4/dist-packages/django/utils/functional.py", line 35, in __get__
    res = instance.__dict__[self.name] = self.func(instance)
  File "/usr/local/lib/python3.4/dist-packages/django/urls/resolvers.py", line 405, in url_patterns
    patterns = getattr(self.urlconf_module, "urlpatterns", self.urlconf_module)
  File "/usr/local/lib/python3.4/dist-packages/django/utils/functional.py", line 35, in __get__
    res = instance.__dict__[self.name] = self.func(instance)
  File "/usr/local/lib/python3.4/dist-packages/django/urls/resolvers.py", line 398, in urlconf_module
    return import_module(self.urlconf_name)
  File "/usr/lib/python3.4/importlib/__init__.py", line 109, in import_module
    return _bootstrap._gcd_import(name[level:], package, level)
  File "<frozen importlib._bootstrap>", line 2254, in _gcd_import
  File "<frozen importlib._bootstrap>", line 2237, in _find_and_load
  File "<frozen importlib._bootstrap>", line 2226, in _find_and_load_unlocked
  File "<frozen importlib._bootstrap>", line 1200, in _load_unlocked
  File "<frozen importlib._bootstrap>", line 1129, in _exec
  File "<frozen importlib._bootstrap>", line 1471, in exec_module
  File "<frozen importlib._bootstrap>", line 321, in _call_with_frames_removed
  File "/workspace/simzi/simzi/urls.py", line 3, in <module>
    from server import views
  File "/workspace/simzi/server/views.py", line 28
    elif contetn == u"처음으로"
                           ^
SyntaxError: invalid syntax
Performing system checks...

Unhandled exception in thread started by <function check_errors.<locals>.wrapper at 0x7faef517cd08>
Traceback (most recent call last):
  File "/usr/local/lib/python3.4/dist-packages/django/utils/autoreload.py", line 228, in wrapper
    fn(*args, **kwargs)
  File "/usr/local/lib/python3.4/dist-packages/django/core/management/commands/runserver.py", line 125, in inner_run
    self.check(display_num_errors=True)
  File "/usr/local/lib/python3.4/dist-packages/django/core/management/base.py", line 359, in check
    include_deployment_checks=include_deployment_checks,
  File "/usr/local/lib/python3.4/dist-packages/django/core/management/base.py", line 346, in _run_checks
    return checks.run_checks(**kwargs)
  File "/usr/local/lib/python3.4/dist-packages/django/core/checks/registry.py", line 81, in run_checks
    new_errors = check(app_configs=app_configs)
  File "/usr/local/lib/python3.4/dist-packages/django/core/checks/urls.py", line 16, in check_url_config
    return check_resolver(resolver)
  File "/usr/local/lib/python3.4/dist-packages/django/core/checks/urls.py", line 26, in check_resolver
    return check_method()
  File "/usr/local/lib/python3.4/dist-packages/django/urls/resolvers.py", line 254, in check
    for pattern in self.url_patterns:
  File "/usr/local/lib/python3.4/dist-packages/django/utils/functional.py", line 35, in __get__
    res = instance.__dict__[self.name] = self.func(instance)
  File "/usr/local/lib/python3.4/dist-packages/django/urls/resolvers.py", line 405, in url_patterns
    patterns = getattr(self.urlconf_module, "urlpatterns", self.urlconf_module)
  File "/usr/local/lib/python3.4/dist-packages/django/utils/functional.py", line 35, in __get__
    res = instance.__dict__[self.name] = self.func(instance)
  File "/usr/local/lib/python3.4/dist-packages/django/urls/resolvers.py", line 398, in urlconf_module
    return import_module(self.urlconf_name)
  File "/usr/lib/python3.4/importlib/__init__.py", line 109, in import_module
    return _bootstrap._gcd_import(name[level:], package, level)
  File "<frozen importlib._bootstrap>", line 2254, in _gcd_import
  File "<frozen importlib._bootstrap>", line 2237, in _find_and_load
  File "<frozen importlib._bootstrap>", line 2226, in _find_and_load_unlocked
  File "<frozen importlib._bootstrap>", line 1200, in _load_unlocked
  File "<frozen importlib._bootstrap>", line 1129, in _exec
  File "<frozen importlib._bootstrap>", line 1471, in exec_module
  File "<frozen importlib._bootstrap>", line 321, in _call_with_frames_removed
  File "/workspace/simzi/simzi/urls.py", line 3, in <module>
    from server import views
  File "/workspace/simzi/server/views.py", line 28
    elif contetn == u"처음으로"
                           ^
SyntaxError: invalid syntax
Performing system checks...

Unhandled exception in thread started by <function check_errors.<locals>.wrapper at 0x7fb595e09d08>
Traceback (most recent call last):
  File "/usr/local/lib/python3.4/dist-packages/django/utils/autoreload.py", line 228, in wrapper
    fn(*args, **kwargs)
  File "/usr/local/lib/python3.4/dist-packages/django/core/management/commands/runserver.py", line 125, in inner_run
    self.check(display_num_errors=True)
  File "/usr/local/lib/python3.4/dist-packages/django/core/management/base.py", line 359, in check
    include_deployment_checks=include_deployment_checks,
  File "/usr/local/lib/python3.4/dist-packages/django/core/management/base.py", line 346, in _run_checks
    return checks.run_checks(**kwargs)
  File "/usr/local/lib/python3.4/dist-packages/django/core/checks/registry.py", line 81, in run_checks
    new_errors = check(app_configs=app_configs)
  File "/usr/local/lib/python3.4/dist-packages/django/core/checks/urls.py", line 16, in check_url_config
    return check_resolver(resolver)
  File "/usr/local/lib/python3.4/dist-packages/django/core/checks/urls.py", line 26, in check_resolver
    return check_method()
  File "/usr/local/lib/python3.4/dist-packages/django/urls/resolvers.py", line 254, in check
    for pattern in self.url_patterns:
  File "/usr/local/lib/python3.4/dist-packages/django/utils/functional.py", line 35, in __get__
    res = instance.__dict__[self.name] = self.func(instance)
  File "/usr/local/lib/python3.4/dist-packages/django/urls/resolvers.py", line 405, in url_patterns
    patterns = getattr(self.urlconf_module, "urlpatterns", self.urlconf_module)
  File "/usr/local/lib/python3.4/dist-packages/django/utils/functional.py", line 35, in __get__
    res = instance.__dict__[self.name] = self.func(instance)
  File "/usr/local/lib/python3.4/dist-packages/django/urls/resolvers.py", line 398, in urlconf_module
    return import_module(self.urlconf_name)
  File "/usr/lib/python3.4/importlib/__init__.py", line 109, in import_module
    return _bootstrap._gcd_import(name[level:], package, level)
  File "<frozen importlib._bootstrap>", line 2254, in _gcd_import
  File "<frozen importlib._bootstrap>", line 2237, in _find_and_load
  File "<frozen importlib._bootstrap>", line 2226, in _find_and_load_unlocked
  File "<frozen importlib._bootstrap>", line 1200, in _load_unlocked
  File "<frozen importlib._bootstrap>", line 1129, in _exec
  File "<frozen importlib._bootstrap>", line 1471, in exec_module
  File "<frozen importlib._bootstrap>", line 321, in _call_with_frames_removed
  File "/workspace/simzi/simzi/urls.py", line 3, in <module>
    from server import views
  File "/workspace/simzi/server/views.py", line 28
    elif content == u"처음으로"
                           ^
SyntaxError: invalid syntax
Performing system checks...

Unhandled exception in thread started by <function check_errors.<locals>.wrapper at 0x7fd975807d08>
Traceback (most recent call last):
  File "/usr/local/lib/python3.4/dist-packages/django/utils/autoreload.py", line 228, in wrapper
    fn(*args, **kwargs)
  File "/usr/local/lib/python3.4/dist-packages/django/core/management/commands/runserver.py", line 125, in inner_run
    self.check(display_num_errors=True)
  File "/usr/local/lib/python3.4/dist-packages/django/core/management/base.py", line 359, in check
    include_deployment_checks=include_deployment_checks,
  File "/usr/local/lib/python3.4/dist-packages/django/core/management/base.py", line 346, in _run_checks
    return checks.run_checks(**kwargs)
  File "/usr/local/lib/python3.4/dist-packages/django/core/checks/registry.py", line 81, in run_checks
    new_errors = check(app_configs=app_configs)
  File "/usr/local/lib/python3.4/dist-packages/django/core/checks/urls.py", line 16, in check_url_config
    return check_resolver(resolver)
  File "/usr/local/lib/python3.4/dist-packages/django/core/checks/urls.py", line 26, in check_resolver
    return check_method()
  File "/usr/local/lib/python3.4/dist-packages/django/urls/resolvers.py", line 254, in check
    for pattern in self.url_patterns:
  File "/usr/local/lib/python3.4/dist-packages/django/utils/functional.py", line 35, in __get__
    res = instance.__dict__[self.name] = self.func(instance)
  File "/usr/local/lib/python3.4/dist-packages/django/urls/resolvers.py", line 405, in url_patterns
    patterns = getattr(self.urlconf_module, "urlpatterns", self.urlconf_module)
  File "/usr/local/lib/python3.4/dist-packages/django/utils/functional.py", line 35, in __get__
    res = instance.__dict__[self.name] = self.func(instance)
  File "/usr/local/lib/python3.4/dist-packages/django/urls/resolvers.py", line 398, in urlconf_module
    return import_module(self.urlconf_name)
  File "/usr/lib/python3.4/importlib/__init__.py", line 109, in import_module
    return _bootstrap._gcd_import(name[level:], package, level)
  File "<frozen importlib._bootstrap>", line 2254, in _gcd_import
  File "<frozen importlib._bootstrap>", line 2237, in _find_and_load
  File "<frozen importlib._bootstrap>", line 2226, in _find_and_load_unlocked
  File "<frozen importlib._bootstrap>", line 1200, in _load_unlocked
  File "<frozen importlib._bootstrap>", line 1129, in _exec
  File "<frozen importlib._bootstrap>", line 1471, in exec_module
  File "<frozen importlib._bootstrap>", line 321, in _call_with_frames_removed
  File "/workspace/simzi/simzi/urls.py", line 3, in <module>
    from server import views
  File "/workspace/simzi/server/views.py", line 28
    elif content == u"처음으로"
                           ^
SyntaxError: invalid syntax
Performing system checks...

Unhandled exception in thread started by <function check_errors.<locals>.wrapper at 0x7f444804dd08>
Traceback (most recent call last):
  File "/usr/local/lib/python3.4/dist-packages/django/utils/autoreload.py", line 228, in wrapper
    fn(*args, **kwargs)
  File "/usr/local/lib/python3.4/dist-packages/django/core/management/commands/runserver.py", line 125, in inner_run
    self.check(display_num_errors=True)
  File "/usr/local/lib/python3.4/dist-packages/django/core/management/base.py", line 359, in check
    include_deployment_checks=include_deployment_checks,
  File "/usr/local/lib/python3.4/dist-packages/django/core/management/base.py", line 346, in _run_checks
    return checks.run_checks(**kwargs)
  File "/usr/local/lib/python3.4/dist-packages/django/core/checks/registry.py", line 81, in run_checks
    new_errors = check(app_configs=app_configs)
  File "/usr/local/lib/python3.4/dist-packages/django/core/checks/urls.py", line 16, in check_url_config
    return check_resolver(resolver)
  File "/usr/local/lib/python3.4/dist-packages/django/core/checks/urls.py", line 26, in check_resolver
    return check_method()
  File "/usr/local/lib/python3.4/dist-packages/django/urls/resolvers.py", line 254, in check
    for pattern in self.url_patterns:
  File "/usr/local/lib/python3.4/dist-packages/django/utils/functional.py", line 35, in __get__
    res = instance.__dict__[self.name] = self.func(instance)
  File "/usr/local/lib/python3.4/dist-packages/django/urls/resolvers.py", line 405, in url_patterns
    patterns = getattr(self.urlconf_module, "urlpatterns", self.urlconf_module)
  File "/usr/local/lib/python3.4/dist-packages/django/utils/functional.py", line 35, in __get__
    res = instance.__dict__[self.name] = self.func(instance)
  File "/usr/local/lib/python3.4/dist-packages/django/urls/resolvers.py", line 398, in urlconf_module
    return import_module(self.urlconf_name)
  File "/usr/lib/python3.4/importlib/__init__.py", line 109, in import_module
    return _bootstrap._gcd_import(name[level:], package, level)
  File "<frozen importlib._bootstrap>", line 2254, in _gcd_import
  File "<frozen importlib._bootstrap>", line 2237, in _find_and_load
  File "<frozen importlib._bootstrap>", line 2226, in _find_and_load_unlocked
  File "<frozen importlib._bootstrap>", line 1200, in _load_unlocked
  File "<frozen importlib._bootstrap>", line 1129, in _exec
  File "<frozen importlib._bootstrap>", line 1471, in exec_module
  File "<frozen importlib._bootstrap>", line 321, in _call_with_frames_removed
  File "/workspace/simzi/simzi/urls.py", line 3, in <module>
    from server import views
  File "/workspace/simzi/server/views.py", line 28
    elif content == u"처음으로"
                           ^
SyntaxError: invalid syntax
Performing system checks...

[03/Aug/2017 01:02:17] "GET /keyboard HTTP/1.1" 200 74
[03/Aug/2017 01:02:19] "POST /message HTTP/1.1" 200 228
[03/Aug/2017 01:02:20] "POST /message HTTP/1.1" 200 225
[03/Aug/2017 01:02:21] "POST /message HTTP/1.1" 200 154
[03/Aug/2017 01:02:23] "POST /message HTTP/1.1" 200 152
Performing system checks...

System check identified no issues (0 silenced).
August 03, 2017 - 01:02:14
Django version 1.11.4, using settings 'simzi.settings'
Starting development server at http://0.0.0.0:80/
Quit the server with CONTROL-C.
